2023-03-11 08:45:30,372 INFO    MainThread:3969 [internal.py:wandb_internal():90] W&B internal server running at pid: 3969, started at: 2023-03-11 08:45:30.371263
2023-03-11 08:45:30,373 DEBUG   HandlerThread:3969 [handler.py:handle_request():130] handle_request: check_version
2023-03-11 08:45:30,373 INFO    WriterThread:3969 [datastore.py:open_for_write():77] open: /workspace/wandb/run-20230311_084529-h4uga9uf/run-h4uga9uf.wandb
2023-03-11 08:45:30,376 DEBUG   SenderThread:3969 [sender.py:send():234] send: header
2023-03-11 08:45:30,377 DEBUG   SenderThread:3969 [sender.py:send_request():248] send_request: check_version
2023-03-11 08:45:30,539 DEBUG   SenderThread:3969 [sender.py:send():234] send: run
2023-03-11 08:45:35,220 ERROR   SenderThread:3969 [retry.py:__call__():126] Retry attempt failed:
Traceback (most recent call last):
  File "/opt/conda/lib/python3.7/site-packages/urllib3/connectionpool.py", line 710, in urlopen
    chunked=chunked,
  File "/opt/conda/lib/python3.7/site-packages/urllib3/connectionpool.py", line 449, in _make_request
    six.raise_from(e, None)
  File "<string>", line 3, in raise_from
  File "/opt/conda/lib/python3.7/site-packages/urllib3/connectionpool.py", line 444, in _make_request
    httplib_response = conn.getresponse()
  File "/opt/conda/lib/python3.7/http/client.py", line 1373, in getresponse
    response.begin()
  File "/opt/conda/lib/python3.7/http/client.py", line 319, in begin
    version, status, reason = self._read_status()
  File "/opt/conda/lib/python3.7/http/client.py", line 288, in _read_status
    raise RemoteDisconnected("Remote end closed connection without"
http.client.RemoteDisconnected: Remote end closed connection without response

During handling of the above exception, another exception occurred:

Traceback (most recent call last):
  File "/opt/conda/lib/python3.7/site-packages/requests/adapters.py", line 499, in send
    timeout=timeout,
  File "/opt/conda/lib/python3.7/site-packages/urllib3/connectionpool.py", line 788, in urlopen
    method, url, error=e, _pool=self, _stacktrace=sys.exc_info()[2]
  File "/opt/conda/lib/python3.7/site-packages/urllib3/util/retry.py", line 550, in increment
    raise six.reraise(type(error), error, _stacktrace)
  File "/opt/conda/lib/python3.7/site-packages/urllib3/packages/six.py", line 769, in reraise
    raise value.with_traceback(tb)
  File "/opt/conda/lib/python3.7/site-packages/urllib3/connectionpool.py", line 710, in urlopen
    chunked=chunked,
  File "/opt/conda/lib/python3.7/site-packages/urllib3/connectionpool.py", line 449, in _make_request
    six.raise_from(e, None)
  File "<string>", line 3, in raise_from
  File "/opt/conda/lib/python3.7/site-packages/urllib3/connectionpool.py", line 444, in _make_request
    httplib_response = conn.getresponse()
  File "/opt/conda/lib/python3.7/http/client.py", line 1373, in getresponse
    response.begin()
  File "/opt/conda/lib/python3.7/http/client.py", line 319, in begin
    version, status, reason = self._read_status()
  File "/opt/conda/lib/python3.7/http/client.py", line 288, in _read_status
    raise RemoteDisconnected("Remote end closed connection without"
urllib3.exceptions.ProtocolError: ('Connection aborted.', RemoteDisconnected('Remote end closed connection without response'))

During handling of the above exception, another exception occurred:

Traceback (most recent call last):
  File "/opt/conda/lib/python3.7/site-packages/wandb/sdk/lib/retry.py", line 102, in __call__
    result = self._call_fn(*args, **kwargs)
  File "/opt/conda/lib/python3.7/site-packages/wandb/sdk/internal/internal_api.py", line 141, in execute
    return self.client.execute(*args, **kwargs)
  File "/opt/conda/lib/python3.7/site-packages/wandb/vendor/gql-0.2.0/gql/client.py", line 52, in execute
    result = self._get_result(document, *args, **kwargs)
  File "/opt/conda/lib/python3.7/site-packages/wandb/vendor/gql-0.2.0/gql/client.py", line 60, in _get_result
    return self.transport.execute(document, *args, **kwargs)
  File "/opt/conda/lib/python3.7/site-packages/wandb/vendor/gql-0.2.0/gql/transport/requests.py", line 38, in execute
    request = requests.post(self.url, **post_args)
  File "/opt/conda/lib/python3.7/site-packages/requests/api.py", line 115, in post
    return request("post", url, data=data, json=json, **kwargs)
  File "/opt/conda/lib/python3.7/site-packages/requests/api.py", line 59, in request
    return session.request(method=method, url=url, **kwargs)
  File "/opt/conda/lib/python3.7/site-packages/requests/sessions.py", line 587, in request
    resp = self.send(prep, **send_kwargs)
  File "/opt/conda/lib/python3.7/site-packages/requests/sessions.py", line 701, in send
    r = adapter.send(request, **kwargs)
  File "/opt/conda/lib/python3.7/site-packages/requests/adapters.py", line 547, in send
    raise ConnectionError(err, request=request)
requests.exceptions.ConnectionError: ('Connection aborted.', RemoteDisconnected('Remote end closed connection without response'))
2023-03-11 08:45:51,321 WARNING MainThread:3969 [internal.py:wandb_internal():146] Internal process interrupt: 1
2023-03-11 08:46:00,000 WARNING MainThread:3969 [internal.py:wandb_internal():146] Internal process interrupt: 2
2023-03-11 08:46:00,001 ERROR   MainThread:3969 [internal.py:wandb_internal():149] Internal process interrupted.
